<?xml version="1.0" ?>
<sdf version="1.8">
    <model name='diff_drive'>
      <link name='chassis'>
        <pose>-0.151427 -0 0.175 0 -0 0</pose>
        <inertial>
          <mass>1.14395</mass>
          <inertia>
            <ixx>0.126164</ixx>
            <ixy>0</ixy>
            <ixz>0</ixz>
            <iyy>0.416519</iyy>
            <iyz>0</iyz>
            <izz>0.481014</izz>
          </inertia>
        </inertial>
        <visual name='visual_chassis'>
          <geometry>
            <box>
              <size>2.01142 1 0.568726</size>
            </box>
          </geometry>
          <material>
            <ambient>0.5 0.5 1.0 1</ambient>
            <diffuse>0.5 0.5 1.0 1</diffuse>
            <specular>0.0 0.0 1.0 1</specular>
          </material>
        </visual>
        <collision name='collision_chassis'>
          <geometry>
            <box>
              <size>2.01142 1 0.568726</size>
            </box>
          </geometry>
        </collision>
      </link>

      <link name='left_wheel'>
        <pose>0.554283 0.625029 -0.025 -1.5707 0 0</pose>
        <inertial>
          <mass>2</mass>
          <inertia>
            <ixx>0.145833</ixx>
            <ixy>0</ixy>
            <ixz>0</ixz>
            <iyy>0.145833</iyy>
            <iyz>0</iyz>
            <izz>0.125</izz>
          </inertia>
        </inertial>
        <visual name='visual_left_wheel'>
          <geometry>
            <sphere>
              <radius>0.3</radius>
            </sphere>
          </geometry>
          <material>
            <ambient>0.2 0.2 0.2 1</ambient>
            <diffuse>0.2 0.2 0.2 1</diffuse>
            <specular>0.2 0.2 0.2 1</specular>
          </material>
        </visual>
        <collision name='collision_left_wheel'>
          <geometry>
            <sphere>
              <radius>0.3</radius>
            </sphere>
          </geometry>
        </collision>
      </link>

      <link name='right_wheel'>
        <pose>0.554282 -0.625029 -0.025 -1.5707 0 0</pose>
        <inertial>
          <mass>2</mass>
          <inertia>
            <ixx>0.145833</ixx>
            <ixy>0</ixy>
            <ixz>0</ixz>
            <iyy>0.145833</iyy>
            <iyz>0</iyz>
            <izz>0.125</izz>
          </inertia>
        </inertial>
        <visual name='visual_right_wheel'>
          <geometry>
            <sphere>
              <radius>0.3</radius>
            </sphere>
          </geometry>
          <material>
            <ambient>0.2 0.2 0.2 1</ambient>
            <diffuse>0.2 0.2 0.2 1</diffuse>
            <specular>0.2 0.2 0.2 1</specular>
          </material>
        </visual>
        <collision name='collision_right_wheel'>
          <geometry>
            <sphere>
              <radius>0.3</radius>
            </sphere>
          </geometry>
        </collision>
      </link>

      <link name='caster'>
        <pose>-0.957138 -0 -0.125 0 -0 0</pose>
        <inertial>
          <mass>1</mass>
          <inertia>
            <ixx>0.1</ixx>
            <ixy>0</ixy>
            <ixz>0</ixz>
            <iyy>0.1</iyy>
            <iyz>0</iyz>
            <izz>0.1</izz>
          </inertia>
        </inertial>
        <visual name='visual_caster'>
          <geometry>
            <sphere>
              <radius>0.2</radius>
            </sphere>
          </geometry>
          <material>
            <ambient>0.2 0.2 0.2 1</ambient>
            <diffuse>0.2 0.2 0.2 1</diffuse>
            <specular>0.2 0.2 0.2 1</specular>
          </material>
        </visual>
        <collision name='collision_caster'>
          <geometry>
            <sphere>
              <radius>0.2</radius>
            </sphere>
          </geometry>
        </collision>
      </link>

      <link name="lidar_link">
        <pose>0 0 0.5 0 0 0</pose>
        <inertial>
          <mass>0.1</mass>
          <inertia>
            <ixx>0.000166667</ixx>
            <iyy>0.000166667</iyy>
            <izz>0.000166667</izz>
          </inertia>
        </inertial>
        <collision name="collision">
          <geometry>
            <box>
              <size>0.1 0.1 0.1</size>
            </box>
          </geometry>
        </collision>
        <visual name="visual">
          <geometry>
            <box>
              <size>0.1 0.1 0.1</size>
            </box>
          </geometry>
        </visual>
        <sensor name='gpu_lidar' type='gpu_lidar'>
          <pose>0 0 0 0 0 0</pose>
          <topic>scan</topic>
           <gz_frame_id>diff_drive/lidar_link</gz_frame_id>
           <frame_id>lidar_link</frame_id>
          <update_rate>10</update_rate>
          <lidar>
            <scan>
              <horizontal>
                <samples>640</samples>
                <resolution>1</resolution>
                <min_angle>-3.141593</min_angle>
                <max_angle>3.141593</max_angle>
              </horizontal>
              <vertical>
                <samples>1</samples>
                <resolution>1</resolution>
                <min_angle>0.0</min_angle>
                <max_angle>0.0</max_angle>
              </vertical>
            </scan>
            <range>
              <min>0.08</min>
              <max>10.0</max>
              <resolution>0.01</resolution>
            </range>
          </lidar>
          <visualize>true</visualize>
        </sensor>
      </link>

      <!-- Depth Camera Link -->
      <link name="depth_camera_link">
        <pose>0.8 0 0.3 0 0 0</pose>
        <inertial>
          <mass>0.05</mass>
          <inertia>
            <ixx>0.000083333</ixx>
            <iyy>0.000083333</iyy>
            <izz>0.000083333</izz>
          </inertia>
        </inertial>
        <collision name="depth_camera_collision">
          <geometry>
            <box>
              <size>0.05 0.15 0.05</size>
            </box>
          </geometry>
        </collision>
        <visual name="depth_camera_visual">
          <geometry>
            <box>
              <size>0.05 0.15 0.05</size>
            </box>
          </geometry>
          <material>
            <ambient>0.1 0.1 0.1 1</ambient>
            <diffuse>0.1 0.1 0.1 1</diffuse>
            <specular>0.1 0.1 0.1 1</specular>
          </material>
        </visual>
        
        <!-- RGB Camera Sensor -->
        <sensor name="rgb_camera" type="camera">
          <pose>0 0 0 0 0 0</pose>
          <topic>rgb/image_raw</topic>
          <gz_frame_id>diff_drive/depth_camera_link</gz_frame_id>
          <frame_id>depth_camera_link</frame_id>
          <update_rate>30</update_rate>
          <camera>
            <horizontal_fov>1.047198</horizontal_fov>
            <image>
              <width>640</width>
              <height>480</height>
              <format>R8G8B8</format>
            </image>
            <clip>
              <near>0.1</near>
              <far>10.0</far>
            </clip>
          </camera>
          <always_on>1</always_on>
          <visualize>true</visualize>
        </sensor>

        <!-- Depth Camera Sensor -->
        <sensor name="depth_camera" type="depth_camera">
          <pose>0 0 0 0 0 0</pose>
          <topic>depth/image_raw</topic>
          <gz_frame_id>diff_drive/depth_camera_link</gz_frame_id>
          <frame_id>depth_camera_link</frame_id>
          <update_rate>30</update_rate>
          <camera>
            <horizontal_fov>1.047198</horizontal_fov>
            <image>
              <width>640</width>
              <height>480</height>
              <format>R_FLOAT32</format>
            </image>
            <clip>
              <near>0.1</near>
              <far>10.0</far>
            </clip>
          </camera>
          <always_on>1</always_on>
          <visualize>false</visualize>
        </sensor>

        <!-- RGBD Camera Sensor (Combined RGB + Depth) -->
        <sensor name="rgbd_camera" type="rgbd_camera">
          <pose>0 0 0 0 0 0</pose>
          <topic>rgbd</topic>
          <gz_frame_id>diff_drive/depth_camera_link</gz_frame_id>
          <frame_id>depth_camera_link</frame_id>
          <update_rate>30</update_rate>
          <camera>
            <horizontal_fov>1.047198</horizontal_fov>
            <image>
              <width>640</width>
              <height>480</height>
              <format>R8G8B8</format>
            </image>
            <depth_image>
              <width>640</width>
              <height>480</height>
              <format>R_FLOAT32</format>
            </depth_image>
            <clip>
              <near>0.1</near>
              <far>10.0</far>
            </clip>
          </camera>
          <always_on>1</always_on>
          <visualize>false</visualize>
        </sensor>
      </link>

      <!-- Joints -->
      <joint name='lidar_joint' type='fixed'>
        <parent>chassis</parent>
        <child>lidar_link</child>
      </joint>

      <joint name='depth_camera_joint' type='fixed'>
        <parent>chassis</parent>
        <child>depth_camera_link</child>
      </joint>

      <joint name='left_wheel_joint' type='revolute'>
        <parent>chassis</parent>
        <child>left_wheel</child>
        <axis>
          <xyz>0 0 1</xyz>
          <limit>
            <lower>-1.79769e+308</lower>
            <upper>1.79769e+308</upper>
          </limit>
        </axis>
      </joint>

      <joint name='right_wheel_joint' type='revolute'>
        <parent>chassis</parent>
        <child>right_wheel</child>
        <axis>
          <xyz>0 0 1</xyz>
          <limit>
            <lower>-1.79769e+308</lower>
            <upper>1.79769e+308</upper>
          </limit>
        </axis>
      </joint>

      <joint name='caster_wheel' type='ball'>
        <parent>chassis</parent>
        <child>caster</child>
      </joint>

    <!-- REPLACE the existing plugin section at the bottom of your SDF with this corrected version -->

    <!-- 1. DiffDrive Plugin (keep as is - this one is correct) -->

<!-- 1. DiffDrive Plugin - FIXED -->


<plugin filename="libgz-sim-diff-drive-system.so" name="gz::sim::systems::DiffDrive">
    <left_joint>left_wheel_joint</left_joint>
    <right_joint>right_wheel_joint</right_joint>
    <wheel_separation>1.25</wheel_separation>  <!-- Distance between wheels -->
    <wheel_radius>0.3</wheel_radius>           <!-- Wheel radius -->
    <odom_publish_frequency>30</odom_publish_frequency>
    <topic>/model/diff_drive/cmd_vel</topic>   <!-- Matches your bridge -->
    <odom_topic>odometry</odom_topic>
</plugin>

<!-- 2. Joint State Publisher Plugin -->
<plugin filename="libgz-sim-joint-state-publisher-system.so" name="gz::sim::systems::JointStatePublisher">
    <joint_name>left_wheel_joint</joint_name>
    <joint_name>right_wheel_joint</joint_name>
    <joint_name>caster_wheel</joint_name>
</plugin>
<!-- 3. Pose Publisher Plugin - For TF -->
<plugin filename="gz-sim-pose-publisher-system" name="gz::sim::systems::PosePublisher">
    <publish_link_pose>true</publish_link_pose>
    <publish_collision_pose>false</publish_collision_pose>
    <publish_visual_pose>false</publish_visual_pose>
    <use_pose_vector_msg>true</use_pose_vector_msg>
    <static_publisher>true</static_publisher>
    <static_update_frequency>1</static_update_frequency>
</plugin>
    </model>
</sdf>
